sqlalchemy.exc.OperationalError: (_mysql_exceptions.OperationalError) (1045, "Access denied for user 'boot'@'localhost' (using password: YES)") (Background on this error at: http://sqlalche.me/e/e3q8)

Error code: 1045 for errors in the username or password variables set in the __init__ function of MySQLConnection class, I changed username back to 'root' to fix


Traceback (most recent call last):
  File "server.py", line 8, in <module>
    print mysql.query_db("SELECT * FROM users")
  File "/Users/michaelmansperger/Desktop/DojoAssignments/Python/python_stack/flask_MySQL/MySQL_Connection_Errors/mysqlconnection.py", line 22, in query_db
    result = self.db.session.execute(text(query), data)
  File "/Users/michaelmansperger/Desktop/DojoAssignments/Python/python_stack/myEnviroments/flaskEnv/lib/python2.7/site-packages/sqlalchemy/orm/scoping.py", line 153, in do
    return getattr(self.registry(), name)(*args, **kwargs)
  File "/Users/michaelmansperger/Desktop/DojoAssignments/Python/python_stack/myEnviroments/flaskEnv/lib/python2.7/site-packages/sqlalchemy/orm/session.py", line 1176, in execute
    bind, close_with_result=True).execute(clause, params or {})
  File "/Users/michaelmansperger/Desktop/DojoAssignments/Python/python_stack/myEnviroments/flaskEnv/lib/python2.7/site-packages/sqlalchemy/orm/session.py", line 1040, in _connection_for_bind
    engine, execution_options)
  File "/Users/michaelmansperger/Desktop/DojoAssignments/Python/python_stack/myEnviroments/flaskEnv/lib/python2.7/site-packages/sqlalchemy/orm/session.py", line 409, in _connection_for_bind
    conn = bind.contextual_connect()
  File "/Users/michaelmansperger/Desktop/DojoAssignments/Python/python_stack/myEnviroments/flaskEnv/lib/python2.7/site-packages/sqlalchemy/engine/base.py", line 2123, in contextual_connect
    self._wrap_pool_connect(self.pool.connect, None),
  File "/Users/michaelmansperger/Desktop/DojoAssignments/Python/python_stack/myEnviroments/flaskEnv/lib/python2.7/site-packages/sqlalchemy/engine/base.py", line 2162, in _wrap_pool_connect
    e, dialect, self)
  File "/Users/michaelmansperger/Desktop/DojoAssignments/Python/python_stack/myEnviroments/flaskEnv/lib/python2.7/site-packages/sqlalchemy/engine/base.py", line 1476, in _handle_dbapi_exception_noconnection
    exc_info
  File "/Users/michaelmansperger/Desktop/DojoAssignments/Python/python_stack/myEnviroments/flaskEnv/lib/python2.7/site-packages/sqlalchemy/util/compat.py", line 203, in raise_from_cause
    reraise(type(exception), exception, tb=exc_tb, cause=cause)
  File "/Users/michaelmansperger/Desktop/DojoAssignments/Python/python_stack/myEnviroments/flaskEnv/lib/python2.7/site-packages/sqlalchemy/engine/base.py", line 2158, in _wrap_pool_connect
    return fn()
  File "/Users/michaelmansperger/Desktop/DojoAssignments/Python/python_stack/myEnviroments/flaskEnv/lib/python2.7/site-packages/sqlalchemy/pool.py", line 403, in connect
    return _ConnectionFairy._checkout(self)
  File "/Users/michaelmansperger/Desktop/DojoAssignments/Python/python_stack/myEnviroments/flaskEnv/lib/python2.7/site-packages/sqlalchemy/pool.py", line 788, in _checkout
    fairy = _ConnectionRecord.checkout(pool)
  File "/Users/michaelmansperger/Desktop/DojoAssignments/Python/python_stack/myEnviroments/flaskEnv/lib/python2.7/site-packages/sqlalchemy/pool.py", line 532, in checkout
    rec = pool._do_get()
  File "/Users/michaelmansperger/Desktop/DojoAssignments/Python/python_stack/myEnviroments/flaskEnv/lib/python2.7/site-packages/sqlalchemy/pool.py", line 1193, in _do_get
    self._dec_overflow()
  File "/Users/michaelmansperger/Desktop/DojoAssignments/Python/python_stack/myEnviroments/flaskEnv/lib/python2.7/site-packages/sqlalchemy/util/langhelpers.py", line 66, in __exit__
    compat.reraise(exc_type, exc_value, exc_tb)
  File "/Users/michaelmansperger/Desktop/DojoAssignments/Python/python_stack/myEnviroments/flaskEnv/lib/python2.7/site-packages/sqlalchemy/pool.py", line 1190, in _do_get
    return self._create_connection()
  File "/Users/michaelmansperger/Desktop/DojoAssignments/Python/python_stack/myEnviroments/flaskEnv/lib/python2.7/site-packages/sqlalchemy/pool.py", line 350, in _create_connection
    return _ConnectionRecord(self)
  File "/Users/michaelmansperger/Desktop/DojoAssignments/Python/python_stack/myEnviroments/flaskEnv/lib/python2.7/site-packages/sqlalchemy/pool.py", line 477, in __init__
    self.__connect(first_connect_check=True)
  File "/Users/michaelmansperger/Desktop/DojoAssignments/Python/python_stack/myEnviroments/flaskEnv/lib/python2.7/site-packages/sqlalchemy/pool.py", line 671, in __connect
    connection = pool._invoke_creator(self)
  File "/Users/michaelmansperger/Desktop/DojoAssignments/Python/python_stack/myEnviroments/flaskEnv/lib/python2.7/site-packages/sqlalchemy/engine/strategies.py", line 106, in connect
    return dialect.connect(*cargs, **cparams)
  File "/Users/michaelmansperger/Desktop/DojoAssignments/Python/python_stack/myEnviroments/flaskEnv/lib/python2.7/site-packages/sqlalchemy/engine/default.py", line 410, in connect
    return self.dbapi.connect(*cargs, **cparams)
  File "/Users/michaelmansperger/Desktop/DojoAssignments/Python/python_stack/myEnviroments/flaskEnv/lib/python2.7/site-packages/MySQLdb/__init__.py", line 81, in Connect
    return Connection(*args, **kwargs)
  File "/Users/michaelmansperger/Desktop/DojoAssignments/Python/python_stack/myEnviroments/flaskEnv/lib/python2.7/site-packages/MySQLdb/connections.py", line 193, in __init__
    super(Connection, self).__init__(*args, **kwargs2)
sqlalchemy.exc.OperationalError: (_mysql_exceptions.OperationalError) (2003, "Can't connect to MySQL server on '127.0.0.1' (61)") (Background on this error at: http://sqlalche.me/e/e3q8)

Connecting to an unopened port produces an error and prints a stack trace. I changed port 3306 to 3307 then back to port 3306 to fix, the same port I used to create/start MySQL server

sqlalchemy.exc.OperationalError: (_mysql_exceptions.OperationalError) (2003, "Can't connect to MySQL server on '127.0.0.1' (61)") (Background on this error at: http://sqlalche.me/e/e3q8)

I changed the name of the database in server.py to an invalid name. I fixed this by changing the name of the database passed to MySQLConnector to a name of a database that exists in MySQL server.

Traceback (most recent call last):
  File "server.py", line 8, in <module>
    print mysql.query_db("SELECT * FROM users")
  File "/Users/michaelmansperger/Desktop/DojoAssignments/Python/python_stack/flask_MySQL/MySQL_Connection_Errors/mysqlconnection.py", line 22, in query_db
    result = self.db.session.execute(text(query), data)
  File "/Users/michaelmansperger/Desktop/DojoAssignments/Python/python_stack/myEnviroments/flaskEnv/lib/python2.7/site-packages/sqlalchemy/orm/scoping.py", line 153, in do
    return getattr(self.registry(), name)(*args, **kwargs)
  File "/Users/michaelmansperger/Desktop/DojoAssignments/Python/python_stack/myEnviroments/flaskEnv/lib/python2.7/site-packages/sqlalchemy/orm/session.py", line 1176, in execute
    bind, close_with_result=True).execute(clause, params or {})
  File "/Users/michaelmansperger/Desktop/DojoAssignments/Python/python_stack/myEnviroments/flaskEnv/lib/python2.7/site-packages/sqlalchemy/orm/session.py", line 1040, in _connection_for_bind
    engine, execution_options)
  File "/Users/michaelmansperger/Desktop/DojoAssignments/Python/python_stack/myEnviroments/flaskEnv/lib/python2.7/site-packages/sqlalchemy/orm/session.py", line 409, in _connection_for_bind
    conn = bind.contextual_connect()
  File "/Users/michaelmansperger/Desktop/DojoAssignments/Python/python_stack/myEnviroments/flaskEnv/lib/python2.7/site-packages/sqlalchemy/engine/base.py", line 2123, in contextual_connect
    self._wrap_pool_connect(self.pool.connect, None),
  File "/Users/michaelmansperger/Desktop/DojoAssignments/Python/python_stack/myEnviroments/flaskEnv/lib/python2.7/site-packages/sqlalchemy/engine/base.py", line 2162, in _wrap_pool_connect
    e, dialect, self)
  File "/Users/michaelmansperger/Desktop/DojoAssignments/Python/python_stack/myEnviroments/flaskEnv/lib/python2.7/site-packages/sqlalchemy/engine/base.py", line 1476, in _handle_dbapi_exception_noconnection
    exc_info
  File "/Users/michaelmansperger/Desktop/DojoAssignments/Python/python_stack/myEnviroments/flaskEnv/lib/python2.7/site-packages/sqlalchemy/util/compat.py", line 203, in raise_from_cause
    reraise(type(exception), exception, tb=exc_tb, cause=cause)
  File "/Users/michaelmansperger/Desktop/DojoAssignments/Python/python_stack/myEnviroments/flaskEnv/lib/python2.7/site-packages/sqlalchemy/engine/base.py", line 2158, in _wrap_pool_connect
    return fn()
  File "/Users/michaelmansperger/Desktop/DojoAssignments/Python/python_stack/myEnviroments/flaskEnv/lib/python2.7/site-packages/sqlalchemy/pool.py", line 403, in connect
    return _ConnectionFairy._checkout(self)
  File "/Users/michaelmansperger/Desktop/DojoAssignments/Python/python_stack/myEnviroments/flaskEnv/lib/python2.7/site-packages/sqlalchemy/pool.py", line 788, in _checkout
    fairy = _ConnectionRecord.checkout(pool)
  File "/Users/michaelmansperger/Desktop/DojoAssignments/Python/python_stack/myEnviroments/flaskEnv/lib/python2.7/site-packages/sqlalchemy/pool.py", line 532, in checkout
    rec = pool._do_get()
  File "/Users/michaelmansperger/Desktop/DojoAssignments/Python/python_stack/myEnviroments/flaskEnv/lib/python2.7/site-packages/sqlalchemy/pool.py", line 1193, in _do_get
    self._dec_overflow()
  File "/Users/michaelmansperger/Desktop/DojoAssignments/Python/python_stack/myEnviroments/flaskEnv/lib/python2.7/site-packages/sqlalchemy/util/langhelpers.py", line 66, in __exit__
    compat.reraise(exc_type, exc_value, exc_tb)
  File "/Users/michaelmansperger/Desktop/DojoAssignments/Python/python_stack/myEnviroments/flaskEnv/lib/python2.7/site-packages/sqlalchemy/pool.py", line 1190, in _do_get
    return self._create_connection()
  File "/Users/michaelmansperger/Desktop/DojoAssignments/Python/python_stack/myEnviroments/flaskEnv/lib/python2.7/site-packages/sqlalchemy/pool.py", line 350, in _create_connection
    return _ConnectionRecord(self)
  File "/Users/michaelmansperger/Desktop/DojoAssignments/Python/python_stack/myEnviroments/flaskEnv/lib/python2.7/site-packages/sqlalchemy/pool.py", line 477, in __init__
    self.__connect(first_connect_check=True)
  File "/Users/michaelmansperger/Desktop/DojoAssignments/Python/python_stack/myEnviroments/flaskEnv/lib/python2.7/site-packages/sqlalchemy/pool.py", line 671, in __connect
    connection = pool._invoke_creator(self)
  File "/Users/michaelmansperger/Desktop/DojoAssignments/Python/python_stack/myEnviroments/flaskEnv/lib/python2.7/site-packages/sqlalchemy/engine/strategies.py", line 106, in connect
    return dialect.connect(*cargs, **cparams)
  File "/Users/michaelmansperger/Desktop/DojoAssignments/Python/python_stack/myEnviroments/flaskEnv/lib/python2.7/site-packages/sqlalchemy/engine/default.py", line 410, in connect
    return self.dbapi.connect(*cargs, **cparams)
  File "/Users/michaelmansperger/Desktop/DojoAssignments/Python/python_stack/myEnviroments/flaskEnv/lib/python2.7/site-packages/MySQLdb/__init__.py", line 81, in Connect
    return Connection(*args, **kwargs)
  File "/Users/michaelmansperger/Desktop/DojoAssignments/Python/python_stack/myEnviroments/flaskEnv/lib/python2.7/site-packages/MySQLdb/connections.py", line 193, in __init__
    super(Connection, self).__init__(*args, **kwargs2)
sqlalchemy.exc.OperationalError: (_mysql_exceptions.OperationalError) (2003, "Can't connect to MySQL server on '127.0.0.1' (61)") (Background on this error at: http://sqlalche.me/e/e3q8)

I changed the config 'host' value from 'localhost' to 'billy' producing the same error code and similar stack trace as changing the database name above. I fixed this by changing the value of 'host' back to 'localhost'

